Line 1: 38348 | 2025-05-12 15:56:38,463 | INFO     | log_context          |   lognk/log_utils.py:50   | Context init ZUXGcQpU
Line 2: 38348 | 2025-05-12 15:56:39,465 | DEBUG    | supermegaprint       |              temp.py:9    | nam kha
Line 3: 38348 | 2025-05-12 15:56:39,465 | DEBUG    | myfunc               |            inside.py:7    | 123
Line 4: 38348 | 2025-05-12 15:56:39,466 | WARNING  | <module>             |              test.py:17   | Loss: 0
Line 5: 38348 | 2025-05-12 15:56:39,466 | CRITICAL | <module>             |              test.py:18   | Loss: 0
Line 6: 38348 | 2025-05-12 15:56:39,466 | DEBUG    | print_something      |     utils/newfunc.py:6    | Im the best
Line 7: 38348 | 2025-05-12 15:56:40,467 | DEBUG    | supermegaprint       |              temp.py:9    | nam kha
Line 8: 38348 | 2025-05-12 15:56:40,467 | DEBUG    | myfunc               |            inside.py:7    | 123
Line 9: 38348 | 2025-05-12 15:56:41,468 | DEBUG    | supermegaprint       |              temp.py:9    | nam kha
Line 10: 38348 | 2025-05-12 15:56:41,468 | DEBUG    | myfunc               |            inside.py:7    | 123
Line 11: 38348 | 2025-05-12 15:56:41,468 | WARNING  | <module>             |              test.py:17   | Loss: 2
Line 12: 38348 | 2025-05-12 15:56:41,468 | CRITICAL | <module>             |              test.py:18   | Loss: 2
Line 13: 38348 | 2025-05-12 15:56:41,468 | DEBUG    | print_something      |     utils/newfunc.py:6    | Im the best
Line 14: 38348 | 2025-05-12 15:56:42,469 | DEBUG    | supermegaprint       |              temp.py:9    | nam kha
Line 15: 38348 | 2025-05-12 15:56:42,470 | ERROR    | log_context          |   lognk/log_utils.py:57   | Traceback (most recent call last):
Line 16:   File "/home/namkha/Documents/mydev/lognk/lognk/log_utils.py", line 54, in log_context
Line 17:     yield
Line 18:   File "/home/namkha/Documents/mydev/lognk/test.py", line 14, in <module>
Line 19:     myprint(idx)
Line 20:   File "/home/namkha/Documents/mydev/lognk/temp.py", line 11, in supermegaprint
Line 21:     with open('temp.txt', 'r') as file:
Line 22: FileNotFoundError: [Errno 2] No such file or directory: 'temp.txt'
Line 23: 
Line 24: 38348 | 2025-05-12 15:56:42,470 | INFO     | log_context          |   lognk/log_utils.py:61   | Context time ZUXGcQpU 4.01 seconds
